2022-06-30 13:13:43,440 INFO    MainThread:18060 [internal.py:wandb_internal():93] W&B internal server running at pid: 18060, started at: 2022-06-30 13:13:43.440248
2022-06-30 13:13:43,443 INFO    WriterThread:18060 [datastore.py:open_for_write():75] open: D:\Documents\codes\python\KnowledgeGraph\LinkPredict\SAC_KGR\src\wandb\run-20220630_131342-1rovoq5r\run-1rovoq5r.wandb
2022-06-30 13:13:43,446 DEBUG   SenderThread:18060 [sender.py:send():232] send: header
2022-06-30 13:13:43,446 DEBUG   SenderThread:18060 [sender.py:send():232] send: run
2022-06-30 13:13:47,110 ERROR   SenderThread:18060 [retry.py:__call__():126] Retry attempt failed:
Traceback (most recent call last):
  File "D:\Programs\Python\Python37\lib\site-packages\urllib3\connectionpool.py", line 700, in urlopen
    self._prepare_proxy(conn)
  File "D:\Programs\Python\Python37\lib\site-packages\urllib3\connectionpool.py", line 994, in _prepare_proxy
    conn.connect()
  File "D:\Programs\Python\Python37\lib\site-packages\urllib3\connection.py", line 364, in connect
    self.sock = conn = self._connect_tls_proxy(hostname, conn)
  File "D:\Programs\Python\Python37\lib\site-packages\urllib3\connection.py", line 505, in _connect_tls_proxy
    ssl_context=ssl_context,
  File "D:\Programs\Python\Python37\lib\site-packages\urllib3\util\ssl_.py", line 453, in ssl_wrap_socket
    ssl_sock = _ssl_wrap_socket_impl(sock, context, tls_in_tls)
  File "D:\Programs\Python\Python37\lib\site-packages\urllib3\util\ssl_.py", line 495, in _ssl_wrap_socket_impl
    return ssl_context.wrap_socket(sock)
  File "D:\Programs\Python\Python37\lib\ssl.py", line 423, in wrap_socket
    session=session
  File "D:\Programs\Python\Python37\lib\ssl.py", line 870, in _create
    self.do_handshake()
  File "D:\Programs\Python\Python37\lib\ssl.py", line 1139, in do_handshake
    self._sslobj.do_handshake()
OSError: [Errno 0] Error

During handling of the above exception, another exception occurred:

Traceback (most recent call last):
  File "D:\Programs\Python\Python37\lib\site-packages\requests\adapters.py", line 450, in send
    timeout=timeout
  File "D:\Programs\Python\Python37\lib\site-packages\urllib3\connectionpool.py", line 786, in urlopen
    method, url, error=e, _pool=self, _stacktrace=sys.exc_info()[2]
  File "D:\Programs\Python\Python37\lib\site-packages\urllib3\util\retry.py", line 592, in increment
    raise MaxRetryError(_pool, url, error or ResponseError(cause))
urllib3.exceptions.MaxRetryError: HTTPSConnectionPool(host='api.wandb.ai', port=443): Max retries exceeded with url: /graphql (Caused by ProxyError('Cannot connect to proxy.', OSError(0, 'Error')))

During handling of the above exception, another exception occurred:

Traceback (most recent call last):
  File "D:\Programs\Python\Python37\lib\site-packages\wandb\sdk\lib\retry.py", line 102, in __call__
    result = self._call_fn(*args, **kwargs)
  File "D:\Programs\Python\Python37\lib\site-packages\wandb\sdk\internal\internal_api.py", line 140, in execute
    return self.client.execute(*args, **kwargs)
  File "D:\Programs\Python\Python37\lib\site-packages\wandb\vendor\gql-0.2.0\wandb_gql\client.py", line 52, in execute
    result = self._get_result(document, *args, **kwargs)
  File "D:\Programs\Python\Python37\lib\site-packages\wandb\vendor\gql-0.2.0\wandb_gql\client.py", line 60, in _get_result
    return self.transport.execute(document, *args, **kwargs)
  File "D:\Programs\Python\Python37\lib\site-packages\wandb\vendor\gql-0.2.0\wandb_gql\transport\requests.py", line 38, in execute
    request = requests.post(self.url, **post_args)
  File "D:\Programs\Python\Python37\lib\site-packages\requests\api.py", line 117, in post
    return request('post', url, data=data, json=json, **kwargs)
  File "D:\Programs\Python\Python37\lib\site-packages\requests\api.py", line 61, in request
    return session.request(method=method, url=url, **kwargs)
  File "D:\Programs\Python\Python37\lib\site-packages\requests\sessions.py", line 529, in request
    resp = self.send(prep, **send_kwargs)
  File "D:\Programs\Python\Python37\lib\site-packages\requests\sessions.py", line 645, in send
    r = adapter.send(request, **kwargs)
  File "D:\Programs\Python\Python37\lib\site-packages\requests\adapters.py", line 513, in send
    raise ProxyError(e, request=request)
requests.exceptions.ProxyError: HTTPSConnectionPool(host='api.wandb.ai', port=443): Max retries exceeded with url: /graphql (Caused by ProxyError('Cannot connect to proxy.', OSError(0, 'Error')))
2022-06-30 13:13:49,967 WARNING MainThread:18060 [internal.py:wandb_internal():153] Internal process interrupt: 1
